<?xml version="1.0"?>
<!-- Auto-generated from kr150_r3100_2_macro.xacro -->
<robot name="kr150_r3100_2">

  <link name="world"/>

  <joint name="world-base_link" type="fixed">
    <parent link="world"/>
    <child link="base_link"/>
    <origin rpy="0 0 0" xyz="0 0 0"/>
  </joint>

    <!-- links - main serial chain -->
    <link name="base_link">
      <collision>
        <geometry>
          <mesh filename="../meshes/kr150_r3100_2/collision/base_link.stl"/>
        </geometry>
        <origin rpy="0.0 -0.0 0.0" xyz="0.0 0.0 0.0"/>
      </collision>
      <visual>
        <geometry>
          <mesh filename="../meshes/kr150_r3100_2/visual/base_link.dae"/>
        </geometry>
        <origin rpy="0.0 -0.0 0.0" xyz="0.0 0.0 0.0"/>
      </visual>
    </link>
    <link name="link_1">
      <collision>
        <geometry>
          <mesh filename="../meshes/kr150_r3100_2/collision/link_1.stl"/>
        </geometry>
        <origin rpy="-3.141592653589793 0.0 -0.0" xyz="0.0 -3.742520618194312e-17 0.30560000000000004"/>
      </collision>
      <visual>
        <geometry>
          <mesh filename="../meshes/kr150_r3100_2/visual/link_1.dae"/>
        </geometry>
        <origin rpy="-3.141592653589793 0.0 -0.0" xyz="0.0 -3.742520618194312e-17 0.30560000000000004"/>
      </visual>
    </link>
    <link name="link_2">
      <collision>
        <geometry>
          <mesh filename="../meshes/kr150_r3100_2/collision/link_2.stl"/>
        </geometry>
        <origin rpy="1.5707963267948968 -0.0 1.5707963267948966" xyz="-0.645 -0.32999999999999996 0.07200000000000009"/>
      </collision>
      <visual>
        <geometry>
          <mesh filename="../meshes/kr150_r3100_2/visual/link_2.dae"/>
        </geometry>
        <origin rpy="1.5707963267948968 -0.0 1.5707963267948966" xyz="-0.645 -0.32999999999999996 0.07200000000000009"/>
      </visual>
    </link>
    <link name="link_3">
      <collision>
        <geometry>
          <mesh filename="../meshes/kr150_r3100_2/collision/link_3.stl"/>
        </geometry>
        <origin rpy="1.5707963267948968 -0.0 -0.0" xyz="-0.33000000000000007 1.995 0.1750000000000001"/>
      </collision>
      <visual>
        <geometry>
          <mesh filename="../meshes/kr150_r3100_2/visual/link_3.dae"/>
        </geometry>
        <origin rpy="1.5707963267948968 -0.0 -0.0" xyz="-0.33000000000000007 1.995 0.1750000000000001"/>
      </visual>
    </link>
    <link name="link_4">
      <collision>
        <geometry>
          <mesh filename="../meshes/kr150_r3100_2/collision/link_4.stl"/>
        </geometry>
        <origin rpy="1.8369701987210297e-16 1.5707963267948966 0.0" xyz="-2.11 2.0519898299681579e-19 1.3579999999999999"/>
      </collision>
      <visual>
        <geometry>
          <mesh filename="../meshes/kr150_r3100_2/visual/link_4.dae"/>
        </geometry>
        <origin rpy="1.8369701987210297e-16 1.5707963267948966 0.0" xyz="-2.11 2.0519898299681579e-19 1.3579999999999999"/>
      </visual>
    </link>
    <link name="link_5">
      <collision>
        <geometry>
          <mesh filename="../meshes/kr150_r3100_2/collision/link_5.stl"/>
        </geometry>
        <origin rpy="1.5707963267948968 -3.749399456654644e-33 -6.123233995736766e-17" xyz="-1.7499999999999998 2.11 -0.09600000000000004"/>
      </collision>
      <visual>
        <geometry>
          <mesh filename="../meshes/kr150_r3100_2/visual/link_5.dae"/>
        </geometry>
        <origin rpy="1.5707963267948968 -3.749399456654644e-33 -6.123233995736766e-17" xyz="-1.7499999999999998 2.11 -0.09600000000000004"/>
      </visual>
    </link>
    <link name="link_6">
      <collision>
        <geometry>
          <mesh filename="../meshes/kr150_r3100_2/collision/link_6.stl"/>
        </geometry>
        <origin rpy="1.2246467991473532e-16 1.5707963267948966 0.0" xyz="-2.1100000000000003 -1.3543772457760985e-16 1.9164999999999999"/>
      </collision>
      <visual>
        <geometry>
          <mesh filename="../meshes/kr150_r3100_2/visual/link_6.dae"/>
        </geometry>
        <origin rpy="1.2246467991473532e-16 1.5707963267948966 0.0" xyz="-2.1100000000000003 -1.3543772457760985e-16 1.9164999999999999"/>
      </visual>
    </link>
    <joint name="joint_1" type="revolute">
      <axis xyz="0.0 0.0 1.0"/>
      <child link="link_1"/>
      <limit effort="7.29E3" lower="-3.2288591125E0" upper="3.2288591125E0" velocity="1.83259571459405E0"/>
      <origin rpy="3.141592653589793 -0.0 0.0" xyz="0.0 0.0 0.30560000000000004"/>
      <parent link="base_link"/>
    </joint>
    <joint name="joint_2" type="revolute">
      <axis xyz="0.0 0.0 1.0"/>
      <child link="link_2"/>
      <limit effort="8.91E3" lower="-2.44346095E0" upper="-8.72664625E-2" velocity="1.86750229963393E0"/>
      <origin rpy="1.5707963267948966 -0.0 0.0" xyz="0.33 0.07200000000000001 -0.3394"/>
      <parent link="link_1"/>
    </joint>
    <joint name="joint_3" type="revolute">
      <axis xyz="0.0 0.0 1.0"/>
      <child link="link_3"/>
      <limit effort="7.53874623365738E3" lower="-2.0943951E0" upper="2.93215314E0" velocity="1.98967534727354E0"/>
      <origin rpy="0.0 -0.0 0.0" xyz="1.35 0.0 -0.10300000000000001"/>
      <parent link="link_2"/>
    </joint>
    <joint name="joint_4" type="revolute">
      <axis xyz="0.0 0.0 1.0"/>
      <child link="link_4"/>
      <limit effort="2.43125052899853E3" lower="-6.108652375E0" upper="6.108652375E0" velocity="3.31612557878923E0"/>
      <origin rpy="1.5707963267948966 -0.0 -1.5707963267948966" xyz="1.028 -0.115 0.17500000000000002"/>
      <parent link="link_3"/>
    </joint>
    <joint name="joint_5" type="revolute">
      <axis xyz="0.0 0.0 1.0"/>
      <child link="link_5"/>
      <limit effort="1.46056085236985E3" lower="-2.1816615625E0" upper="2.1816615625E0" velocity="3.14159265358979E0"/>
      <origin rpy="0.0 1.5707963267948966 1.5707963267948966" xyz="0.0 0.096 -0.392"/>
      <parent link="link_4"/>
    </joint>
    <joint name="joint_6" type="revolute">
      <axis xyz="0.0 0.0 1.0"/>
      <child link="link_6"/>
      <limit effort="8.92539E2" lower="-6.108652375E0" upper="6.108652375E0" velocity="4.53785605518526E0"/>
      <origin rpy="1.5707963267948966 -0.0 -1.5707963267948966" xyz="0.1665 0.0 -0.096"/>
      <parent link="link_5"/>
    </joint>
    <!-- ROS-Industrial 'base' frame - equivalent of 'KUKA ROBROOT'-->
    <link name="base"/>
    <joint name="base_link-base" type="fixed">
      <origin xyz="0 0 0" rpy="0 0 0"/>
      <parent link="base_link"/>
      <child link="base"/>
    </joint>
    <!-- ROS-Industrial 'flange' frame - attachment point for EEF models -->
    <link name="flange"/>
    <joint name="link6-flange" type="fixed">
      <child link="flange"/>
      <origin rpy="0.0 1.5707963267948966 0.0" xyz="0.0 0.0 -0.0485"/>
      <parent link="link_6"/>
    </joint>
    <!-- ROS-Industrial 'tool0' frame - all-zeros tool frame -->
    <link name="tool0"/>
    <joint name="link6-tool0" type="fixed">
      <child link="tool0"/>
      <origin rpy="3.141592653589793 1.2246467991473532E-16 3.141592653589793" xyz="0.0 0.0 -0.0485"/>
      <parent link="link_6"/>
    </joint>
  
</robot>
