<?xml version="1.0"?>
<!-- Auto-generated from kr210_r3100_ultra_macro.xacro -->
<robot name="kr210_r3100_ultra">

  <link name="world"/>

  <joint name="world-base_link" type="fixed">
    <parent link="world"/>
    <child link="base_link"/>
    <origin rpy="0 0 0" xyz="0 0 0"/>
  </joint>

    <link name="base"/>
    <link name="base_link">
      <collision>
        <geometry>
          <mesh filename="../meshes/kr210_r3100_ultra/collision/base_link.stl"/>
        </geometry>
        <origin rpy="0.0 -0.0 0.0" xyz="0.0 0.0 0.0"/>
      </collision>
      <visual>
        <geometry>
          <mesh filename="../meshes/kr210_r3100_ultra/visual/base_link.dae"/>
        </geometry>
        <origin rpy="0.0 -0.0 0.0" xyz="0.0 0.0 0.0"/>
      </visual>
    </link>
    <link name="flange"/>
    <link name="link_1">
      <collision>
        <geometry>
          <mesh filename="../meshes/kr210_r3100_ultra/collision/link_1.stl"/>
        </geometry>
        <origin rpy="0.0 -0.0 0.0" xyz="0.0 0.0 -0.675"/>
      </collision>
      <visual>
        <geometry>
          <mesh filename="../meshes/kr210_r3100_ultra/visual/link_1.dae"/>
        </geometry>
        <origin rpy="0.0 -0.0 0.0" xyz="0.0 0.0 -0.675"/>
      </visual>
    </link>
    <link name="link_2">
      <collision>
        <geometry>
          <mesh filename="../meshes/kr210_r3100_ultra/collision/link_2.stl"/>
        </geometry>
        <origin rpy="1.5707963267948966 0.0 1.5707963267948966" xyz="-0.675 -0.35 4.133182947122317e-17"/>
      </collision>
      <visual>
        <geometry>
          <mesh filename="../meshes/kr210_r3100_ultra/visual/link_2.dae"/>
        </geometry>
        <origin rpy="1.5707963267948966 0.0 1.5707963267948966" xyz="-0.675 -0.35 4.133182947122317e-17"/>
      </visual>
    </link>
    <link name="link_3">
      <collision>
        <geometry>
          <mesh filename="../meshes/kr210_r3100_ultra/collision/link_3.stl"/>
        </geometry>
        <origin rpy="1.5707963267948966 0.0 1.5707963267948966" xyz="-2.0250000000000004 -0.35 4.1331829471223196e-17"/>
      </collision>
      <visual>
        <geometry>
          <mesh filename="../meshes/kr210_r3100_ultra/visual/link_3.dae"/>
        </geometry>
        <origin rpy="1.5707963267948966 0.0 1.5707963267948966" xyz="-2.0250000000000004 -0.35 4.1331829471223196e-17"/>
      </visual>
    </link>
    <link name="link_4">
      <collision>
        <geometry>
          <mesh filename="../meshes/kr210_r3100_ultra/collision/link_4.stl"/>
        </geometry>
        <origin rpy="3.141592653589793 1.5707963267948966 0.0" xyz="1.9840000000000002 -6.582476545417024e-17 1.75"/>
      </collision>
      <visual>
        <geometry>
          <mesh filename="../meshes/kr210_r3100_ultra/visual/link_4.dae"/>
        </geometry>
        <origin rpy="3.141592653589793 1.5707963267948966 0.0" xyz="1.9840000000000002 -6.582476545417024e-17 1.75"/>
      </visual>
    </link>
    <link name="link_5">
      <collision>
        <geometry>
          <mesh filename="../meshes/kr210_r3100_ultra/collision/link_5.stl"/>
        </geometry>
        <origin rpy="1.5707963267948966 0.0 1.5707963267948966" xyz="-1.9840000000000002 -1.75 4.133182947122316e-17"/>
      </collision>
      <visual>
        <geometry>
          <mesh filename="../meshes/kr210_r3100_ultra/visual/link_5.dae"/>
        </geometry>
        <origin rpy="1.5707963267948966 0.0 1.5707963267948966" xyz="-1.9840000000000002 -1.75 4.133182947122316e-17"/>
      </visual>
    </link>
    <link name="link_6">
      <collision>
        <geometry>
          <mesh filename="../meshes/kr210_r3100_ultra/collision/link_6.stl"/>
        </geometry>
        <origin rpy="3.141592653589793 1.5707963267948966 0.0" xyz="1.9840000000000002 -6.582476545417024e-17 1.75"/>
      </collision>
      <visual>
        <geometry>
          <mesh filename="../meshes/kr210_r3100_ultra/visual/link_6.dae"/>
        </geometry>
        <origin rpy="3.141592653589793 1.5707963267948966 0.0" xyz="1.9840000000000002 -6.582476545417024e-17 1.75"/>
      </visual>
    </link>
    <link name="tool0"/>
    <joint name="base_link-base" type="fixed">
      <child link="base"/>
      <parent link="base_link"/>
    </joint>
    <joint name="joint_1" type="revolute">
      <axis xyz="0.0 0.0 1.0"/>
      <child link="link_1"/>
      <limit effort="9.6E3" lower="-3.2288591125E0" upper="3.2288591125E0" velocity="1.84E0"/>
      <origin rpy="0.0 0.0 0.0" xyz="0.0 0.0 0.675"/>
      <parent link="base_link"/>
    </joint>
    <joint name="joint_2" type="revolute">
      <axis xyz="0.0 0.0 1.0"/>
      <child link="link_2"/>
      <limit effort="9.6E3" lower="-2.44346095E0" upper="-8.72664625E-2" velocity="1.77E0"/>
      <origin rpy="-1.5707963267948966 -0.0 0.0" xyz="0.35000000000000003 0.0 0.0"/>
      <parent link="link_1"/>
    </joint>
    <joint name="joint_3" type="revolute">
      <axis xyz="0.0 0.0 1.0"/>
      <child link="link_3"/>
      <limit effort="6.64852E3" lower="-2.0943951E0" upper="2.7052603375E0" velocity="1.87E0"/>
      <origin rpy="0.0 -0.0 -1.5707963267948966" xyz="1.35 0.0 0.0"/>
      <parent link="link_2"/>
    </joint>
    <joint name="joint_4" type="revolute">
      <axis xyz="0.0 0.0 1.0"/>
      <child link="link_4"/>
      <limit effort="2.17309E3" lower="-6.108652375E0" upper="6.108652375E0" velocity="2.37E0"/>
      <origin rpy="1.5707963267948966 -0.0 0.0" xyz="-0.041 1.4000000000000001 0.0"/>
      <parent link="link_3"/>
    </joint>
    <joint name="joint_5" type="revolute">
      <axis xyz="0.0 0.0 1.0"/>
      <child link="link_5"/>
      <limit effort="2.17309E3" lower="-2.13802833125E0" upper="2.13802833125E0" velocity="2.26E0"/>
      <origin rpy="-1.5707963267948966 -0.0 0.0" xyz="0.0 0.0 0.0"/>
      <parent link="link_4"/>
    </joint>
    <joint name="joint_6" type="revolute">
      <axis xyz="0.0 0.0 1.0"/>
      <child link="link_6"/>
      <limit effort="1.26875E3" lower="-6.108652375E0" upper="6.108652375E0" velocity="3.6E0"/>
      <origin rpy="1.5707963267948966 -0.0 0.0" xyz="0.0 0.0 0.0"/>
      <parent link="link_5"/>
    </joint>
    <joint name="link6-flange" type="fixed">
      <child link="flange"/>
      <origin rpy="0.0 1.5707963267948966 0.0" xyz="0.0 0.0 -0.24"/>
      <parent link="link_6"/>
    </joint>
    <joint name="link6-tool0" type="fixed">
      <child link="tool0"/>
      <origin rpy="0.0 ${pi} 0.0" xyz="0.0 0.0 -0.24"/>
      <parent link="link_6"/>
    </joint>
  
</robot>
