<?xml version="1.0"?>
<!-- Auto-generated from kr4_r600_macro.xacro -->
<robot name="kr4_r600">

  <link name="world"/>

  <joint name="world-base_link" type="fixed">
    <parent link="world"/>
    <child link="base_link"/>
    <origin rpy="0 0 0" xyz="0 0 0"/>
  </joint>

    <link name="base"/>
    <link name="base_link">
      <collision>
        <geometry>
          <mesh filename="../meshes/kr4_r600/collision/base_link.stl"/>
        </geometry>
        <origin rpy="0.0 -0.0 0.0" xyz="0.0 0.0 0.0"/>
      </collision>
      <visual>
        <geometry>
          <mesh filename="../meshes/kr4_r600/visual/base_link.dae"/>
        </geometry>
        <origin rpy="0.0 -0.0 0.0" xyz="0.0 0.0 0.0"/>
      </visual>
    </link>
    <link name="flange"/>
    <link name="link_1">
      <collision>
        <geometry>
          <mesh filename="../meshes/kr4_r600/collision/link_1.stl"/>
        </geometry>
        <origin rpy="-3.141592653589793 0.0 -0.0" xyz="0.0 -1.8296223179261457e-17 0.1494"/>
      </collision>
      <visual>
        <geometry>
          <mesh filename="../meshes/kr4_r600/visual/link_1.dae"/>
        </geometry>
        <origin rpy="-3.141592653589793 0.0 -0.0" xyz="0.0 -1.8296223179261457e-17 0.1494"/>
      </visual>
    </link>
    <link name="link_2">
      <collision>
        <geometry>
          <mesh filename="../meshes/kr4_r600/collision/link_2.stl"/>
        </geometry>
        <origin rpy="1.5707963267948968 -0.0 1.5707963267948966" xyz="-0.33 2.020667218593133e-17 -0.06359999999999998"/>
      </collision>
      <visual>
        <geometry>
          <mesh filename="../meshes/kr4_r600/visual/link_2.dae"/>
        </geometry>
        <origin rpy="1.5707963267948968 -0.0 1.5707963267948966" xyz="-0.33 2.020667218593133e-17 -0.06359999999999998"/>
      </visual>
    </link>
    <link name="link_3">
      <collision>
        <geometry>
          <mesh filename="../meshes/kr4_r600/collision/link_3.stl"/>
        </geometry>
        <origin rpy="1.5707963267948968 -0.0 -0.0" xyz="-1.775737858763662e-17 0.62 -0.05899999999999997"/>
      </collision>
      <visual>
        <geometry>
          <mesh filename="../meshes/kr4_r600/visual/link_3.dae"/>
        </geometry>
        <origin rpy="1.5707963267948968 -0.0 -0.0" xyz="-1.775737858763662e-17 0.62 -0.05899999999999997"/>
      </visual>
    </link>
    <link name="link_4">
      <collision>
        <geometry>
          <mesh filename="../meshes/kr4_r600/collision/link_4.stl"/>
        </geometry>
        <origin rpy="1.8369701987210297e-16 1.5707963267948966 0.0" xyz="-0.64 3.32343745553842e-17 0.16940000000000002"/>
      </collision>
      <visual>
        <geometry>
          <mesh filename="../meshes/kr4_r600/visual/link_4.dae"/>
        </geometry>
        <origin rpy="1.8369701987210297e-16 1.5707963267948966 0.0" xyz="-0.64 3.32343745553842e-17 0.16940000000000002"/>
      </visual>
    </link>
    <link name="link_5">
      <collision>
        <geometry>
          <mesh filename="../meshes/kr4_r600/collision/link_5.stl"/>
        </geometry>
        <origin rpy="1.5707963267948968 -3.749399456654644e-33 -6.123233995736766e-17" xyz="-0.31 0.64 -0.045"/>
      </collision>
      <visual>
        <geometry>
          <mesh filename="../meshes/kr4_r600/visual/link_5.dae"/>
        </geometry>
        <origin rpy="1.5707963267948968 -3.749399456654644e-33 -6.123233995736766e-17" xyz="-0.31 0.64 -0.045"/>
      </visual>
    </link>
    <link name="link_6">
      <collision>
        <geometry>
          <mesh filename="../meshes/kr4_r600/collision/link_6.stl"/>
        </geometry>
        <origin rpy="1.2246467991473532e-16 1.5707963267948966 0.0" xyz="-0.64 -3.533106015540123e-18 0.3565"/>
      </collision>
      <visual>
        <geometry>
          <mesh filename="../meshes/kr4_r600/visual/link_6.dae"/>
        </geometry>
        <origin rpy="1.2246467991473532e-16 1.5707963267948966 0.0" xyz="-0.64 -3.533106015540123e-18 0.3565"/>
      </visual>
    </link>
    <link name="tool0"/>
    <joint name="base_link-base" type="fixed">
      <child link="base"/>
      <parent link="base_link"/>
    </joint>
    <joint name="joint_1" type="revolute">
      <axis xyz="0.0 0.0 1.0"/>
      <child link="link_1"/>
      <limit effort="1.1901599999999999E2" lower="-2.967059725E0" upper="2.967059725E0" velocity="5.8643062867009474E0"/>
      <origin rpy="3.141592653589793 -0.0 0.0" xyz="0.0 0.0 0.1494"/>
      <parent link="base_link"/>
    </joint>
    <joint name="joint_2" type="revolute">
      <axis xyz="0.0 0.0 1.0"/>
      <child link="link_2"/>
      <limit effort="1.058514984E2" lower="-3.4033920375E0" upper="6.981317E-1" velocity="5.8643062867009474E0"/>
      <origin rpy="1.5707963267948966 -0.0 0.0" xyz="0.0 -0.0636 -0.1806"/>
      <parent link="link_1"/>
    </joint>
    <joint name="joint_3" type="revolute">
      <axis xyz="0.0 0.0 1.0"/>
      <child link="link_3"/>
      <limit effort="5.431496248E1" lower="-2.0071286375E0" upper="2.617993875E0" velocity="8.5084763634811011E0"/>
      <origin rpy="0.0 -0.0 0.0" xyz="0.29 0.0 -0.004599999999999999"/>
      <parent link="link_2"/>
    </joint>
    <joint name="joint_4" type="revolute">
      <axis xyz="0.0 0.0 1.0"/>
      <child link="link_4"/>
      <limit effort="1.181160928E1" lower="-3.2288591125E0" upper="3.2288591125E0" velocity="1.0471962421996588E1"/>
      <origin rpy="1.5707963267948966 -0.0 -1.5707963267948966" xyz="0.16940000000000002 -0.02 -0.059000000000000004"/>
      <parent link="link_3"/>
    </joint>
    <joint name="joint_5" type="revolute">
      <axis xyz="0.0 0.0 1.0"/>
      <child link="link_5"/>
      <limit effort="1.232779518E1" lower="-2.0943951E0" upper="2.0943951E0" velocity="9.23453476366542E0"/>
      <origin rpy="0.0 1.5707963267948966 1.5707963267948966" xyz="0.0 0.045 -0.1406"/>
      <parent link="link_4"/>
    </joint>
    <joint name="joint_6" type="revolute">
      <axis xyz="0.0 0.0 1.0"/>
      <child link="link_6"/>
      <limit effort="6.916321312E0" lower="-6.108652375E0" upper="6.108652375E0" velocity="1.3962634015954636E1"/>
      <origin rpy="1.5707963267948966 -0.0 -1.5707963267948966" xyz="0.0465 0.0 -0.045"/>
      <parent link="link_5"/>
    </joint>
    <joint name="link6-flange" type="fixed">
      <child link="flange"/>
      <origin rpy="0.0 1.5707963267948966 0.0" xyz="0.0 0.0 -0.0285"/>
      <parent link="link_6"/>
    </joint>
    <joint name="link6-tool0" type="fixed">
      <child link="tool0"/>
      <origin rpy="3.141592653589793 1.2246467991473532E-16 3.141592653589793" xyz="0.0 0.0 -0.0285"/>
      <parent link="link_6"/>
    </joint>
  
</robot>
