<?xml version="1.0"?>
<!-- Auto-generated from kr12_r1450_3_hw_macro.xacro -->
<robot name="kr12_r1450_3">

  <link name="world"/>

  <joint name="world-base_link" type="fixed">
    <parent link="world"/>
    <child link="base_link"/>
    <origin rpy="0 0 0" xyz="0 0 0"/>
  </joint>

    <link name="base"/>
    <link name="base_link">
      <collision>
        <geometry>
          <mesh filename="../meshes/kr12_r1450_3_hw/collision/base_link.stl"/>
        </geometry>
        <origin rpy="0.0 -0.0 0.0" xyz="0.0 0.0 0.0"/>
      </collision>
      <visual>
        <geometry>
          <mesh filename="../meshes/kr12_r1450_3_hw/visual/base_link.dae"/>
        </geometry>
        <origin rpy="0.0 -0.0 0.0" xyz="0.0 0.0 0.0"/>
      </visual>
    </link>
    <link name="flange"/>
    <link name="link_1">
      <collision>
        <geometry>
          <mesh filename="../meshes/kr12_r1450_3_hw/collision/link_1.stl"/>
        </geometry>
        <origin rpy="-3.141592653589793 0.0 -0.0" xyz="0.0 -1.7512449227807152e-17 0.14300000000000002"/>
      </collision>
      <visual>
        <geometry>
          <mesh filename="../meshes/kr12_r1450_3_hw/visual/link_1.dae"/>
        </geometry>
        <origin rpy="-3.141592653589793 0.0 -0.0" xyz="0.0 -1.7512449227807152e-17 0.14300000000000002"/>
      </visual>
    </link>
    <link name="link_2">
      <collision>
        <geometry>
          <mesh filename="../meshes/kr12_r1450_3_hw/collision/link_2.stl"/>
        </geometry>
        <origin rpy="1.5707963267948968 -0.0 1.5707963267948966" xyz="-0.374 -0.16499999999999998 0.08340000000000004"/>
      </collision>
      <visual>
        <geometry>
          <mesh filename="../meshes/kr12_r1450_3_hw/visual/link_2.dae"/>
        </geometry>
        <origin rpy="1.5707963267948968 -0.0 1.5707963267948966" xyz="-0.374 -0.16499999999999998 0.08340000000000004"/>
      </visual>
    </link>
    <link name="link_3">
      <collision>
        <geometry>
          <mesh filename="../meshes/kr12_r1450_3_hw/collision/link_3.stl"/>
        </geometry>
        <origin rpy="1.5707963267948968 -0.0 -0.0" xyz="-0.16500000000000004 0.934 0.07544500000000004"/>
      </collision>
      <visual>
        <geometry>
          <mesh filename="../meshes/kr12_r1450_3_hw/visual/link_3.dae"/>
        </geometry>
        <origin rpy="1.5707963267948968 -0.0 -0.0" xyz="-0.16500000000000004 0.934 0.07544500000000004"/>
      </visual>
    </link>
    <link name="link_4">
      <collision>
        <geometry>
          <mesh filename="../meshes/kr12_r1450_3_hw/collision/link_4.stl"/>
        </geometry>
        <origin rpy="1.8369701987210297e-16 1.5707963267948966 0.0" xyz="-1.122 1.678228889588536e-17 0.454"/>
      </collision>
      <visual>
        <geometry>
          <mesh filename="../meshes/kr12_r1450_3_hw/visual/link_4.dae"/>
        </geometry>
        <origin rpy="1.8369701987210297e-16 1.5707963267948966 0.0" xyz="-1.122 1.678228889588536e-17 0.454"/>
      </visual>
    </link>
    <link name="link_5">
      <collision>
        <geometry>
          <mesh filename="../meshes/kr12_r1450_3_hw/collision/link_5.stl"/>
        </geometry>
        <origin rpy="1.5707963267948968 -3.749399456654644e-33 -6.123233995736766e-17" xyz="-0.8651999999999999 1.122 0.0645"/>
      </collision>
      <visual>
        <geometry>
          <mesh filename="../meshes/kr12_r1450_3_hw/visual/link_5.dae"/>
        </geometry>
        <origin rpy="1.5707963267948968 -3.749399456654644e-33 -6.123233995736766e-17" xyz="-0.8651999999999999 1.122 0.0645"/>
      </visual>
    </link>
    <link name="link_6">
      <collision>
        <geometry>
          <mesh filename="../meshes/kr12_r1450_3_hw/collision/link_6.stl"/>
        </geometry>
        <origin rpy="1.2246467991473532e-16 1.5707963267948966 0.0" xyz="-1.1220000000000003 -5.249702461892625e-17 0.9167"/>
      </collision>
      <visual>
        <geometry>
          <mesh filename="../meshes/kr12_r1450_3_hw/visual/link_6.dae"/>
        </geometry>
        <origin rpy="1.2246467991473532e-16 1.5707963267948966 0.0" xyz="-1.1220000000000003 -5.249702461892625e-17 0.9167"/>
      </visual>
    </link>
    <link name="tool0"/>
    <joint name="base_link-base" type="fixed">
      <child link="base"/>
      <parent link="base_link"/>
    </joint>
    <joint name="joint_1" type="revolute">
      <axis xyz="0.0 0.0 1.0"/>
      <child link="link_1"/>
      <limit effort="7.1712E2" lower="-2.967059725E0" upper="2.967059725E0" velocity="3.1415926535897931E0"/>
      <origin rpy="3.141592653589793 -0.0 0.0" xyz="0.0 0.0 0.14300000000000002"/>
      <parent link="base_link"/>
    </joint>
    <joint name="joint_2" type="revolute">
      <axis xyz="0.0 0.0 1.0"/>
      <child link="link_2"/>
      <limit effort="6.4717893753510191E2" lower="-3.2288591125E0" upper="1.1344640125E0" velocity="2.9670597283903604E0"/>
      <origin rpy="1.5707963267948966 -0.0 0.0" xyz="0.165 0.0834 -0.231"/>
      <parent link="link_1"/>
    </joint>
    <joint name="joint_3" type="revolute">
      <axis xyz="0.0 0.0 1.0"/>
      <child link="link_3"/>
      <limit effort="3.7800154574697081E2" lower="-2.0943951E0" upper="3.14159265E0" velocity="4.5378560551852569E0"/>
      <origin rpy="0.0 -0.0 0.0" xyz="0.56 0.0 0.007954999999999999"/>
      <parent link="link_2"/>
    </joint>
    <joint name="joint_4" type="revolute">
      <axis xyz="0.0 0.0 1.0"/>
      <child link="link_4"/>
      <limit effort="5.4835130643148524E1" lower="-3.14159265E0" upper="3.14159265E0" velocity="7.5049157835756173E0"/>
      <origin rpy="1.5707963267948966 -0.0 -1.5707963267948966" xyz="0.289 -0.188 0.075445"/>
      <parent link="link_3"/>
    </joint>
    <joint name="joint_5" type="revolute">
      <axis xyz="0.0 0.0 1.0"/>
      <child link="link_5"/>
      <limit effort="4.96756170567014E1" lower="-2.44346095E0" upper="2.44346095E0" velocity="7.8539816339744828E0"/>
      <origin rpy="0.0 1.5707963267948966 1.5707963267948966" xyz="0.0 -0.0645 -0.4112"/>
      <parent link="link_4"/>
    </joint>
    <joint name="joint_6" type="revolute">
      <axis xyz="0.0 0.0 1.0"/>
      <child link="link_6"/>
      <limit effort="2.8117123201915362E1" lower="-6.108652375E0" upper="6.108652375E0" velocity="1.2566370614359172E1"/>
      <origin rpy="1.5707963267948966 -0.0 -1.5707963267948966" xyz="0.051500000000000004 0.0 0.0645"/>
      <parent link="link_5"/>
    </joint>
    <joint name="link6-flange" type="fixed">
      <child link="flange"/>
      <origin rpy="0.0 1.5707963267948966 0.0" xyz="0.0 0.0 -0.0285"/>
      <parent link="link_6"/>
    </joint>
    <joint name="link6-tool0" type="fixed">
      <child link="tool0"/>
      <origin rpy="3.141592653589793 1.2246467991473532E-16 3.141592653589793" xyz="0.0 0.0 -0.0285"/>
      <parent link="link_6"/>
    </joint>
  
</robot>
