<?xml version="1.0"?>
<!-- Auto-generated from kr20_r1810_2_macro.xacro -->
<robot name="kr20_r1810_2">

  <link name="world"/>

  <joint name="world-base_link" type="fixed">
    <parent link="world"/>
    <child link="base_link"/>
    <origin rpy="0 0 0" xyz="0 0 0"/>
  </joint>

    <link name="base"/>
    <link name="base_link">
      <collision>
        <geometry>
          <mesh filename="../meshes/kr20_r1810_2/collision/base_link.stl"/>
        </geometry>
        <origin rpy="0.0 -0.0 0.0" xyz="0.0 0.0 0.0"/>
      </collision>
      <visual>
        <geometry>
          <mesh filename="../meshes/kr20_r1810_2/visual/base_link.dae"/>
        </geometry>
        <origin rpy="0.0 -0.0 0.0" xyz="0.0 0.0 0.0"/>
      </visual>
    </link>
    <link name="flange"/>
    <link name="link_1">
      <collision>
        <geometry>
          <mesh filename="../meshes/kr20_r1810_2/collision/link_1.stl"/>
        </geometry>
        <origin rpy="-3.141592653589793 0.0 -0.0" xyz="0.0 -3.8294705409337735e-17 0.3127"/>
      </collision>
      <visual>
        <geometry>
          <mesh filename="../meshes/kr20_r1810_2/visual/link_1.dae"/>
        </geometry>
        <origin rpy="-3.141592653589793 0.0 -0.0" xyz="0.0 -3.8294705409337735e-17 0.3127"/>
      </visual>
    </link>
    <link name="link_2">
      <collision>
        <geometry>
          <mesh filename="../meshes/kr20_r1810_2/collision/link_2.stl"/>
        </geometry>
        <origin rpy="1.5707963267948968 -0.0 1.5707963267948966" xyz="-0.52 -0.15999999999999998 7.013552218716891e-17"/>
      </collision>
      <visual>
        <geometry>
          <mesh filename="../meshes/kr20_r1810_2/visual/link_2.dae"/>
        </geometry>
        <origin rpy="1.5707963267948968 -0.0 1.5707963267948966" xyz="-0.52 -0.15999999999999998 7.013552218716891e-17"/>
      </visual>
    </link>
    <link name="link_3">
      <collision>
        <geometry>
          <mesh filename="../meshes/kr20_r1810_2/collision/link_3.stl"/>
        </geometry>
        <origin rpy="1.5707963267948968 -0.0 -0.0" xyz="-0.16000000000000006 1.3 7.013552218716891e-17"/>
      </collision>
      <visual>
        <geometry>
          <mesh filename="../meshes/kr20_r1810_2/visual/link_3.dae"/>
        </geometry>
        <origin rpy="1.5707963267948968 -0.0 -0.0" xyz="-0.16000000000000006 1.3 7.013552218716891e-17"/>
      </visual>
    </link>
    <link name="link_4">
      <collision>
        <geometry>
          <mesh filename="../meshes/kr20_r1810_2/collision/link_4.stl"/>
        </geometry>
        <origin rpy="1.8369701987210297e-16 1.5707963267948966 0.0" xyz="-1.45 3.419213863219409e-17 0.587"/>
      </collision>
      <visual>
        <geometry>
          <mesh filename="../meshes/kr20_r1810_2/visual/link_4.dae"/>
        </geometry>
        <origin rpy="1.8369701987210297e-16 1.5707963267948966 0.0" xyz="-1.45 3.419213863219409e-17 0.587"/>
      </visual>
    </link>
    <link name="link_5">
      <collision>
        <geometry>
          <mesh filename="../meshes/kr20_r1810_2/collision/link_5.stl"/>
        </geometry>
        <origin rpy="1.5707963267948968 -3.749399456654644e-33 -6.123233995736766e-17" xyz="-1.02 1.45 7.862232450525983e-18"/>
      </collision>
      <visual>
        <geometry>
          <mesh filename="../meshes/kr20_r1810_2/visual/link_5.dae"/>
        </geometry>
        <origin rpy="1.5707963267948968 -3.749399456654644e-33 -6.123233995736766e-17" xyz="-1.02 1.45 7.862232450525983e-18"/>
      </visual>
    </link>
    <link name="link_6">
      <collision>
        <geometry>
          <mesh filename="../meshes/kr20_r1810_2/collision/link_6.stl"/>
        </geometry>
        <origin rpy="1.2246467991473532e-16 1.5707963267948966 0.0" xyz="-1.4500000000000002 -6.396330231946625e-17 1.1729999999999996"/>
      </collision>
      <visual>
        <geometry>
          <mesh filename="../meshes/kr20_r1810_2/visual/link_6.dae"/>
        </geometry>
        <origin rpy="1.2246467991473532e-16 1.5707963267948966 0.0" xyz="-1.4500000000000002 -6.396330231946625e-17 1.1729999999999996"/>
      </visual>
    </link>
    <link name="tool0"/>
    <joint name="base_link-base" type="fixed">
      <child link="base"/>
      <parent link="base_link"/>
    </joint>
    <joint name="joint_1" type="revolute">
      <axis xyz="0.0 0.0 1.0"/>
      <child link="link_1"/>
      <limit effort="1.8096E3" lower="-3.2288591125E0" upper="3.2288591125E0" velocity="3.4906585E0"/>
      <origin rpy="3.141592653589793 -0.0 0.0" xyz="0.0 0.0 0.3127"/>
      <parent link="base_link"/>
    </joint>
    <joint name="joint_2" type="revolute">
      <axis xyz="0.0 0.0 1.0"/>
      <child link="link_2"/>
      <limit effort="1.56910108031E3" lower="-3.2288591125E0" upper="1.1344640125E0" velocity="2.99485184567895E0"/>
      <origin rpy="1.5707963267948966 -0.0 0.0" xyz="0.16 0.0 -0.2073"/>
      <parent link="link_1"/>
    </joint>
    <joint name="joint_3" type="revolute">
      <axis xyz="0.0 0.0 1.0"/>
      <child link="link_3"/>
      <limit effort="7.9265293994E2" lower="-2.408554365E0" upper="3.0543261875E0" velocity="3.31612558E0"/>
      <origin rpy="0.0 -0.0 0.0" xyz="0.78 0.0 0.0"/>
      <parent link="link_2"/>
    </joint>
    <joint name="joint_4" type="revolute">
      <axis xyz="0.0 0.0 1.0"/>
      <child link="link_4"/>
      <limit effort="2.4907279191E2" lower="-6.108652375E0" upper="6.108652375E0" velocity="7.50491578E0"/>
      <origin rpy="1.5707963267948966 -0.0 -1.5707963267948966" xyz="0.427 -0.15 0.0"/>
      <parent link="link_3"/>
    </joint>
    <joint name="joint_5" type="revolute">
      <axis xyz="0.0 0.0 1.0"/>
      <child link="link_5"/>
      <limit effort="2.3886712523E2" lower="-2.268928025E0" upper="2.268928025E0" velocity="7.50491578E0"/>
      <origin rpy="0.0 1.5707963267948966 1.5707963267948966" xyz="0.0 0.0 -0.433"/>
      <parent link="link_4"/>
    </joint>
    <joint name="joint_6" type="revolute">
      <axis xyz="0.0 0.0 1.0"/>
      <child link="link_6"/>
      <limit effort="1.046412E2" lower="-6.108652375E0" upper="6.108652375E0" velocity="1.099557429E1"/>
      <origin rpy="1.5707963267948966 -0.0 -1.5707963267948966" xyz="0.153 0.0 0.0"/>
      <parent link="link_5"/>
    </joint>
    <joint name="link6-flange" type="fixed">
      <child link="flange"/>
      <origin rpy="0.0 1.5707963267948966 0.0" xyz="0.0 0.0 0.0"/>
      <parent link="link_6"/>
    </joint>
    <joint name="link6-tool0" type="fixed">
      <child link="tool0"/>
      <origin rpy="3.141592653589793 1.2246467991473532E-16 3.141592653589793" xyz="0.0 0.0 0.0"/>
      <parent link="link_6"/>
    </joint>
  
</robot>
