<?xml version="1.0"?>
<!-- Auto-generated from kr8_r2100_2_arc_hw_macro.xacro -->
<robot name="kr8_r2100_2">

  <link name="world"/>

  <joint name="world-base_link" type="fixed">
    <parent link="world"/>
    <child link="base_link"/>
    <origin rpy="0 0 0" xyz="0 0 0"/>
  </joint>

    <link name="base"/>
    <link name="base_link">
      <collision>
        <geometry>
          <mesh filename="../meshes/kr8_r2100_2_arc_hw/collision/base_link.stl"/>
        </geometry>
        <origin rpy="0.0 -0.0 0.0" xyz="0.0 0.0 0.0"/>
      </collision>
      <visual>
        <geometry>
          <mesh filename="../meshes/kr8_r2100_2_arc_hw/visual/base_link.dae"/>
        </geometry>
        <origin rpy="0.0 -0.0 0.0" xyz="0.0 0.0 0.0"/>
      </visual>
    </link>
    <link name="flange"/>
    <link name="link_1">
      <collision>
        <geometry>
          <mesh filename="../meshes/kr8_r2100_2_arc_hw/collision/link_1.stl"/>
        </geometry>
        <origin rpy="-3.141592653589793 0.0 -0.0" xyz="0.0 -3.8294705409337735e-17 0.3127"/>
      </collision>
      <visual>
        <geometry>
          <mesh filename="../meshes/kr8_r2100_2_arc_hw/visual/link_1.dae"/>
        </geometry>
        <origin rpy="-3.141592653589793 0.0 -0.0" xyz="0.0 -3.8294705409337735e-17 0.3127"/>
      </visual>
    </link>
    <link name="link_2">
      <collision>
        <geometry>
          <mesh filename="../meshes/kr8_r2100_2_arc_hw/collision/link_2.stl"/>
        </geometry>
        <origin rpy="1.5707963267948968 -0.0 1.5707963267948966" xyz="-0.52 -0.15999999999999998 0.06430000000000007"/>
      </collision>
      <visual>
        <geometry>
          <mesh filename="../meshes/kr8_r2100_2_arc_hw/visual/link_2.dae"/>
        </geometry>
        <origin rpy="1.5707963267948968 -0.0 1.5707963267948966" xyz="-0.52 -0.15999999999999998 0.06430000000000007"/>
      </visual>
    </link>
    <link name="link_3">
      <collision>
        <geometry>
          <mesh filename="../meshes/kr8_r2100_2_arc_hw/collision/link_3.stl"/>
        </geometry>
        <origin rpy="1.5707963267948968 -0.0 -0.0" xyz="-0.16000000000000006 1.5 0.07660000000000007"/>
      </collision>
      <visual>
        <geometry>
          <mesh filename="../meshes/kr8_r2100_2_arc_hw/visual/link_3.dae"/>
        </geometry>
        <origin rpy="1.5707963267948968 -0.0 -0.0" xyz="-0.16000000000000006 1.5 0.07660000000000007"/>
      </visual>
    </link>
    <link name="link_4">
      <collision>
        <geometry>
          <mesh filename="../meshes/kr8_r2100_2_arc_hw/collision/link_4.stl"/>
        </geometry>
        <origin rpy="1.8369701987210297e-16 1.5707963267948966 0.0" xyz="-1.72 2.5041036069705178e-17 0.5766"/>
      </collision>
      <visual>
        <geometry>
          <mesh filename="../meshes/kr8_r2100_2_arc_hw/visual/link_4.dae"/>
        </geometry>
        <origin rpy="1.8369701987210297e-16 1.5707963267948966 0.0" xyz="-1.72 2.5041036069705178e-17 0.5766"/>
      </visual>
    </link>
    <link name="link_5">
      <collision>
        <geometry>
          <mesh filename="../meshes/kr8_r2100_2_arc_hw/collision/link_5.stl"/>
        </geometry>
        <origin rpy="1.5707963267948968 -3.749399456654644e-33 -6.123233995736766e-17" xyz="-1.0950000000000002 1.72 0.04149999999999999"/>
      </collision>
      <visual>
        <geometry>
          <mesh filename="../meshes/kr8_r2100_2_arc_hw/visual/link_5.dae"/>
        </geometry>
        <origin rpy="1.5707963267948968 -3.749399456654644e-33 -6.123233995736766e-17" xyz="-1.0950000000000002 1.72 0.04149999999999999"/>
      </visual>
    </link>
    <link name="link_6">
      <collision>
        <geometry>
          <mesh filename="../meshes/kr8_r2100_2_arc_hw/collision/link_6.stl"/>
        </geometry>
        <origin rpy="1.2246467991473532e-16 1.5707963267948966 0.0" xyz="-1.7200000000000002 -8.833780868240262e-17 1.1614999999999998"/>
      </collision>
      <visual>
        <geometry>
          <mesh filename="../meshes/kr8_r2100_2_arc_hw/visual/link_6.dae"/>
        </geometry>
        <origin rpy="1.2246467991473532e-16 1.5707963267948966 0.0" xyz="-1.7200000000000002 -8.833780868240262e-17 1.1614999999999998"/>
      </visual>
    </link>
    <link name="tool0"/>
    <joint name="base_link-base" type="fixed">
      <child link="base"/>
      <parent link="base_link"/>
    </joint>
    <joint name="joint_1" type="revolute">
      <axis xyz="0.0 0.0 1.0"/>
      <child link="link_1"/>
      <limit effort="2.0009999999999995E3" lower="-3.2288591125E0" upper="3.2288591125E0" velocity="3.4906585039886591E0"/>
      <origin rpy="3.141592653589793 -0.0 0.0" xyz="0.0 0.0 0.3127"/>
      <parent link="base_link"/>
    </joint>
    <joint name="joint_2" type="revolute">
      <axis xyz="0.0 0.0 1.0"/>
      <child link="link_2"/>
      <limit effort="1.7507279369169439E3" lower="-3.2288591125E0" upper="1.1344640125E0" velocity="2.9948518456789457E0"/>
      <origin rpy="1.5707963267948966 -0.0 0.0" xyz="0.16 0.0643 -0.2073"/>
      <parent link="link_1"/>
    </joint>
    <joint name="joint_3" type="revolute">
      <axis xyz="0.0 0.0 1.0"/>
      <child link="link_3"/>
      <limit effort="9.1006343021482007E2" lower="-2.408554365E0" upper="3.0543261875E0" velocity="3.3161255787892263E0"/>
      <origin rpy="0.0 -0.0 0.0" xyz="0.98 0.0 -0.012299999999999997"/>
      <parent link="link_2"/>
    </joint>
    <joint name="joint_4" type="revolute">
      <axis xyz="0.0 0.0 1.0"/>
      <child link="link_4"/>
      <limit effort="5.189173423E1" lower="-2.8797932625E0" upper="2.8797932625E0" velocity="7.5049157835756173E0"/>
      <origin rpy="1.5707963267948966 -0.0 -1.5707963267948966" xyz="0.4166 -0.22 0.0766"/>
      <parent link="link_3"/>
    </joint>
    <joint name="joint_5" type="revolute">
      <axis xyz="0.0 0.0 1.0"/>
      <child link="link_5"/>
      <limit effort="3.6942942428836325E1" lower="-2.0071286375E0" upper="2.44346095E0" velocity="7.5049157835756173E0"/>
      <origin rpy="0.0 1.5707963267948966 1.5707963267948966" xyz="0.0 -0.0415 -0.5184"/>
      <parent link="link_4"/>
    </joint>
    <joint name="joint_6" type="revolute">
      <axis xyz="0.0 0.0 1.0"/>
      <child link="link_6"/>
      <limit effort="3.92448E1" lower="-6.108652375E0" upper="6.108652375E0" velocity="1.0995574287564276E1"/>
      <origin rpy="1.5707963267948966 -0.0 -1.5707963267948966" xyz="0.0665 0.0 0.0415"/>
      <parent link="link_5"/>
    </joint>
    <joint name="link6-flange" type="fixed">
      <child link="flange"/>
      <origin rpy="0.0 1.5707963267948966 0.0" xyz="0.0 0.0 -0.0135"/>
      <parent link="link_6"/>
    </joint>
    <joint name="link6-tool0" type="fixed">
      <child link="tool0"/>
      <origin rpy="3.141592653589793 1.2246467991473532E-16 3.141592653589793" xyz="0.0 0.0 -0.0135"/>
      <parent link="link_6"/>
    </joint>
  
</robot>
