<?xml version="1.0"?>
<!-- Auto-generated from kr8_r1440_2_arc_hw_macro.xacro -->
<robot name="kr8_r1440_2">

  <link name="world"/>

  <joint name="world-base_link" type="fixed">
    <parent link="world"/>
    <child link="base_link"/>
    <origin rpy="0 0 0" xyz="0 0 0"/>
  </joint>

    <link name="base"/>
    <link name="base_link">
      <collision>
        <geometry>
          <mesh filename="../meshes/kr8_r1440_2_arc_hw/collision/base_link.stl"/>
        </geometry>
        <origin rpy="0.0 -0.0 0.0" xyz="0.0 0.0 0.0"/>
      </collision>
      <visual>
        <geometry>
          <mesh filename="../meshes/kr8_r1440_2_arc_hw/visual/base_link.dae"/>
        </geometry>
        <origin rpy="0.0 -0.0 0.0" xyz="0.0 0.0 0.0"/>
      </visual>
    </link>
    <link name="flange"/>
    <link name="link_1">
      <collision>
        <geometry>
          <mesh filename="../meshes/kr8_r1440_2_arc_hw/collision/link_1.stl"/>
        </geometry>
        <origin rpy="-3.141592653589793 0.0 -0.0" xyz="0.0 -3.08610993385133e-17 0.252"/>
      </collision>
      <visual>
        <geometry>
          <mesh filename="../meshes/kr8_r1440_2_arc_hw/visual/link_1.dae"/>
        </geometry>
        <origin rpy="-3.141592653589793 0.0 -0.0" xyz="0.0 -3.08610993385133e-17 0.252"/>
      </visual>
    </link>
    <link name="link_2">
      <collision>
        <geometry>
          <mesh filename="../meshes/kr8_r1440_2_arc_hw/collision/link_2.stl"/>
        </geometry>
        <origin rpy="1.5707963267948968 -0.0 1.5707963267948966" xyz="-0.42500000000000004 -0.16999999999999998 0.07050000000000006"/>
      </collision>
      <visual>
        <geometry>
          <mesh filename="../meshes/kr8_r1440_2_arc_hw/visual/link_2.dae"/>
        </geometry>
        <origin rpy="1.5707963267948968 -0.0 1.5707963267948966" xyz="-0.42500000000000004 -0.16999999999999998 0.07050000000000006"/>
      </visual>
    </link>
    <link name="link_3">
      <collision>
        <geometry>
          <mesh filename="../meshes/kr8_r1440_2_arc_hw/collision/link_3.stl"/>
        </geometry>
        <origin rpy="1.5707963267948968 -0.0 -0.0" xyz="-0.17000000000000004 1.0350000000000001 0.06450000000000007"/>
      </collision>
      <visual>
        <geometry>
          <mesh filename="../meshes/kr8_r1440_2_arc_hw/visual/link_3.dae"/>
        </geometry>
        <origin rpy="1.5707963267948968 -0.0 -0.0" xyz="-0.17000000000000004 1.0350000000000001 0.06450000000000007"/>
      </visual>
    </link>
    <link name="link_4">
      <collision>
        <geometry>
          <mesh filename="../meshes/kr8_r1440_2_arc_hw/collision/link_4.stl"/>
        </geometry>
        <origin rpy="1.8369701987210297e-16 1.5707963267948966 0.0" xyz="-1.245 3.4524881442055596e-17 0.2786"/>
      </collision>
      <visual>
        <geometry>
          <mesh filename="../meshes/kr8_r1440_2_arc_hw/visual/link_4.dae"/>
        </geometry>
        <origin rpy="1.8369701987210297e-16 1.5707963267948966 0.0" xyz="-1.245 3.4524881442055596e-17 0.2786"/>
      </visual>
    </link>
    <link name="link_5">
      <collision>
        <geometry>
          <mesh filename="../meshes/kr8_r1440_2_arc_hw/collision/link_5.stl"/>
        </geometry>
        <origin rpy="1.5707963267948968 -3.749399456654644e-33 -6.123233995736766e-17" xyz="-0.7969999999999999 1.245 0.04150000000000002"/>
      </collision>
      <visual>
        <geometry>
          <mesh filename="../meshes/kr8_r1440_2_arc_hw/visual/link_5.dae"/>
        </geometry>
        <origin rpy="1.5707963267948968 -3.749399456654644e-33 -6.123233995736766e-17" xyz="-0.7969999999999999 1.245 0.04150000000000002"/>
      </visual>
    </link>
    <link name="link_6">
      <collision>
        <geometry>
          <mesh filename="../meshes/kr8_r1440_2_arc_hw/collision/link_6.stl"/>
        </geometry>
        <origin rpy="1.2246467991473532e-16 1.5707963267948966 0.0" xyz="-1.245 -4.976860183030259e-17 0.8634999999999999"/>
      </collision>
      <visual>
        <geometry>
          <mesh filename="../meshes/kr8_r1440_2_arc_hw/visual/link_6.dae"/>
        </geometry>
        <origin rpy="1.2246467991473532e-16 1.5707963267948966 0.0" xyz="-1.245 -4.976860183030259e-17 0.8634999999999999"/>
      </visual>
    </link>
    <link name="tool0"/>
    <joint name="base_link-base" type="fixed">
      <child link="base"/>
      <parent link="base_link"/>
    </joint>
    <joint name="joint_1" type="revolute">
      <axis xyz="0.0 0.0 1.0"/>
      <child link="link_1"/>
      <limit effort="1.296E3" lower="-2.967059725E0" upper="2.967059725E0" velocity="3.83972435438753E0"/>
      <origin rpy="3.141592653589793 -0.0 0.0" xyz="0.0 0.0 0.252"/>
      <parent link="base_link"/>
    </joint>
    <joint name="joint_2" type="revolute">
      <axis xyz="0.0 0.0 1.0"/>
      <child link="link_2"/>
      <limit effort="1.27558721617737E3" lower="-3.2288591125E0" upper="1.1344640125E0" velocity="3.66519142918809E0"/>
      <origin rpy="1.5707963267948966 -0.0 0.0" xyz="0.17 0.07050000000000001 -0.17300000000000001"/>
      <parent link="link_1"/>
    </joint>
    <joint name="joint_3" type="revolute">
      <axis xyz="0.0 0.0 1.0"/>
      <child link="link_3"/>
      <limit effort="2.48615274672424E2" lower="-2.0769418075E0" upper="3.1590459425E0" velocity="4.71238898038469E0"/>
      <origin rpy="0.0 -0.0 0.0" xyz="0.61 0.0 0.006"/>
      <parent link="link_2"/>
    </joint>
    <joint name="joint_4" type="revolute">
      <axis xyz="0.0 0.0 1.0"/>
      <child link="link_4"/>
      <limit effort="4.40443155739045E1" lower="-2.8797932625E0" upper="2.8797932625E0" velocity="7.50491578357562E0"/>
      <origin rpy="1.5707963267948966 -0.0 -1.5707963267948966" xyz="0.1086 -0.21 0.0645"/>
      <parent link="link_3"/>
    </joint>
    <joint name="joint_5" type="revolute">
      <axis xyz="0.0 0.0 1.0"/>
      <child link="link_5"/>
      <limit effort="3.43574585837906E1" lower="-2.0071286375E0" upper="2.44346095E0" velocity="7.50491578357562E0"/>
      <origin rpy="0.0 1.5707963267948966 1.5707963267948966" xyz="0.0 -0.0415 -0.5184"/>
      <parent link="link_4"/>
    </joint>
    <joint name="joint_6" type="revolute">
      <axis xyz="0.0 0.0 1.0"/>
      <child link="link_6"/>
      <limit effort="3.66552E1" lower="-6.108652375E0" upper="6.108652375E0" velocity="1.09706410125358E1"/>
      <origin rpy="1.5707963267948966 -0.0 -1.5707963267948966" xyz="0.0665 0.0 0.0415"/>
      <parent link="link_5"/>
    </joint>
    <joint name="link6-flange" type="fixed">
      <child link="flange"/>
      <origin rpy="0.0 1.5707963267948966 0.0" xyz="0.0 0.0 -0.0135"/>
      <parent link="link_6"/>
    </joint>
    <joint name="link6-tool0" type="fixed">
      <child link="tool0"/>
      <origin rpy="3.141592653589793 1.2246467991473532E-16 3.141592653589793" xyz="0.0 0.0 -0.0135"/>
      <parent link="link_6"/>
    </joint>
  
</robot>
