<?xml version="1.0"?>
<!-- Auto-generated from kr50_r2500_macro.xacro -->
<robot name="kr50_r2500">

  <link name="world"/>

  <joint name="world-base_link" type="fixed">
    <parent link="world"/>
    <child link="base_link"/>
    <origin rpy="0 0 0" xyz="0 0 0"/>
  </joint>

    <link name="base"/>
    <link name="base_link">
      <collision>
        <geometry>
          <mesh filename="../meshes/kr50_r2500/collision/base_link.stl"/>
        </geometry>
        <origin rpy="0.0 -0.0 0.0" xyz="0.0 0.0 0.0"/>
      </collision>
      <visual>
        <geometry>
          <mesh filename="../meshes/kr50_r2500/visual/base_link.dae"/>
        </geometry>
        <origin rpy="0.0 -0.0 0.0" xyz="0.0 0.0 0.0"/>
      </visual>
    </link>
    <link name="flange"/>
    <link name="link_1">
      <collision>
        <geometry>
          <mesh filename="../meshes/kr50_r2500/collision/link_1.stl"/>
        </geometry>
        <origin rpy="-3.141592653589793 0.0 -0.0" xyz="0.0 -2.890166445987754e-17 0.23600000000000002"/>
      </collision>
      <visual>
        <geometry>
          <mesh filename="../meshes/kr50_r2500/visual/link_1.dae"/>
        </geometry>
        <origin rpy="-3.141592653589793 0.0 -0.0" xyz="0.0 -2.890166445987754e-17 0.23600000000000002"/>
      </visual>
    </link>
    <link name="link_2">
      <collision>
        <geometry>
          <mesh filename="../meshes/kr50_r2500/collision/link_2.stl"/>
        </geometry>
        <origin rpy="1.5707963267948968 -0.0 1.5707963267948966" xyz="-0.5750000000000001 -0.175 0.05400000000000006"/>
      </collision>
      <visual>
        <geometry>
          <mesh filename="../meshes/kr50_r2500/visual/link_2.dae"/>
        </geometry>
        <origin rpy="1.5707963267948968 -0.0 1.5707963267948966" xyz="-0.5750000000000001 -0.175 0.05400000000000006"/>
      </visual>
    </link>
    <link name="link_3">
      <collision>
        <geometry>
          <mesh filename="../meshes/kr50_r2500/collision/link_3.stl"/>
        </geometry>
        <origin rpy="1.5707963267948968 -0.0 -0.0" xyz="-0.1750000000000001 1.865 0.15150000000000005"/>
      </collision>
      <visual>
        <geometry>
          <mesh filename="../meshes/kr50_r2500/visual/link_3.dae"/>
        </geometry>
        <origin rpy="1.5707963267948968 -0.0 -0.0" xyz="-0.1750000000000001 1.865 0.15150000000000005"/>
      </visual>
    </link>
    <link name="link_4">
      <collision>
        <geometry>
          <mesh filename="../meshes/kr50_r2500/collision/link_4.stl"/>
        </geometry>
        <origin rpy="1.8369701987210297e-16 1.5707963267948966 0.0" xyz="-1.915 4.025548071885061e-17 0.48305"/>
      </collision>
      <visual>
        <geometry>
          <mesh filename="../meshes/kr50_r2500/visual/link_4.dae"/>
        </geometry>
        <origin rpy="1.8369701987210297e-16 1.5707963267948966 0.0" xyz="-1.915 4.025548071885061e-17 0.48305"/>
      </visual>
    </link>
    <link name="link_5">
      <collision>
        <geometry>
          <mesh filename="../meshes/kr50_r2500/collision/link_5.stl"/>
        </geometry>
        <origin rpy="1.5707963267948968 -3.749399456654644e-33 -6.123233995736766e-17" xyz="-1.21 1.915 -0.04795000000000001"/>
      </collision>
      <visual>
        <geometry>
          <mesh filename="../meshes/kr50_r2500/visual/link_5.dae"/>
        </geometry>
        <origin rpy="1.5707963267948968 -3.749399456654644e-33 -6.123233995736766e-17" xyz="-1.21 1.915 -0.04795000000000001"/>
      </visual>
    </link>
    <link name="link_6">
      <collision>
        <geometry>
          <mesh filename="../meshes/kr50_r2500/collision/link_6.stl"/>
        </geometry>
        <origin rpy="1.2246467991473532e-16 1.5707963267948966 0.0" xyz="-1.9150000000000003 -7.512976725390683e-17 1.359"/>
      </collision>
      <visual>
        <geometry>
          <mesh filename="../meshes/kr50_r2500/visual/link_6.dae"/>
        </geometry>
        <origin rpy="1.2246467991473532e-16 1.5707963267948966 0.0" xyz="-1.9150000000000003 -7.512976725390683e-17 1.359"/>
      </visual>
    </link>
    <link name="tool0"/>
    <joint name="base_link-base" type="fixed">
      <child link="base"/>
      <parent link="base_link"/>
    </joint>
    <joint name="joint_1" type="revolute">
      <axis xyz="0.0 0.0 1.0"/>
      <child link="link_1"/>
      <limit effort="5.528892E3" lower="-3.2288591125E0" upper="3.2288591125E0" velocity="3.05432619099008E0"/>
      <origin rpy="3.141592653589793 -0.0 0.0" xyz="0.0 0.0 0.23600000000000002"/>
      <parent link="base_link"/>
    </joint>
    <joint name="joint_2" type="revolute">
      <axis xyz="0.0 0.0 1.0"/>
      <child link="link_2"/>
      <limit effort="5.10434981145836E3" lower="-3.0543261875E0" upper="1.04719755E0" velocity="2.75719614004311E0"/>
      <origin rpy="1.5707963267948966 -0.0 0.0" xyz="0.17500000000000002 0.054 -0.339"/>
      <parent link="link_1"/>
    </joint>
    <joint name="joint_3" type="revolute">
      <axis xyz="0.0 0.0 1.0"/>
      <child link="link_3"/>
      <limit effort="1.44187791653396E3" lower="-2.0943951E0" upper="2.967059725E0" velocity="3.05432619099008E0"/>
      <origin rpy="0.0 -0.0 0.0" xyz="1.29 0.0 -0.0975"/>
      <parent link="link_2"/>
    </joint>
    <joint name="joint_4" type="revolute">
      <axis xyz="0.0 0.0 1.0"/>
      <child link="link_4"/>
      <limit effort="5.35609199111578E2" lower="-3.14159265E0" upper="3.14159265E0" velocity="4.36332312998582E0"/>
      <origin rpy="1.5707963267948966 -0.0 -1.5707963267948966" xyz="0.30805 -0.05 0.1515"/>
      <parent link="link_3"/>
    </joint>
    <joint name="joint_5" type="revolute">
      <axis xyz="0.0 0.0 1.0"/>
      <child link="link_5"/>
      <limit effort="4.83521521925849E2" lower="-2.1816615625E0" upper="2.1816615625E0" velocity="4.36332312998582E0"/>
      <origin rpy="0.0 1.5707963267948966 1.5707963267948966" xyz="0.0 0.047950000000000007 -0.7269500000000001"/>
      <parent link="link_4"/>
    </joint>
    <joint name="joint_6" type="revolute">
      <axis xyz="0.0 0.0 1.0"/>
      <child link="link_6"/>
      <limit effort="3.38503348259152E2" lower="-6.108652375E0" upper="6.108652375E0" velocity="6.28318530717959E0"/>
      <origin rpy="1.5707963267948966 -0.0 -1.5707963267948966" xyz="0.149 0.0 -0.047950000000000007"/>
      <parent link="link_5"/>
    </joint>
    <joint name="link6-flange" type="fixed">
      <child link="flange"/>
      <origin rpy="0.0 1.5707963267948966 0.0" xyz="0.0 0.0 -0.036000000000000004"/>
      <parent link="link_6"/>
    </joint>
    <joint name="link6-tool0" type="fixed">
      <child link="tool0"/>
      <origin rpy="3.141592653589793 1.2246467991473532E-16 3.141592653589793" xyz="0.0 0.0 -0.036000000000000004"/>
      <parent link="link_6"/>
    </joint>
  
</robot>
